<?xml version="1.0" encoding="UTF-8"?>
<testsuite name="unittest.loader._FailedTest-20240629204734" tests="2" file="unittest/loader.py" time="0.005" timestamp="2024-06-29T20:47:34" failures="0" errors="2" skipped="0">
	<testcase classname="unittest.loader._FailedTest" name="date_tests" time="0.003" timestamp="2024-06-29T20:47:34">
		<error type="ImportError" message="Failed to import test module: date_tests
Traceback (most recent call last):
  File &quot;C:\Users\Celia\AppData\Local\Programs\Python\Python312\Lib\unittest\loader.py&quot;, line 129, in loadTestsFromName
    module = __import__(module_name)
             ^^^^^^^^^^^^^^^^^^^^^^^
  File &quot;c:\users\celia\python_scripts\testingcenter\src\unittest\python\date_tests.py&quot;, line 3, in &lt;module&gt;
    from tester import Date
ModuleNotFoundError: No module named 'tester'
"><![CDATA[Traceback (most recent call last):
  File "C:\Users\Celia\AppData\Local\Programs\Python\Python312\Lib\unittest\case.py", line 58, in testPartExecutor
    yield
  File "C:\Users\Celia\AppData\Local\Programs\Python\Python312\Lib\unittest\case.py", line 634, in run
    self._callTestMethod(testMethod)
    ^^^^^^^^^^^^^^^^^
  File "C:\Users\Celia\AppData\Local\Programs\Python\Python312\Lib\unittest\case.py", line 589, in _callTestMethod
    if method() is not None:
    ^^^^^^^^^^^^^^^^^
  File "C:\Users\Celia\AppData\Local\Programs\Python\Python312\Lib\unittest\loader.py", line 33, in testFailure
    raise self._exception
    ^^^^^^^^^^^^^^^^^
ImportError: Failed to import test module: date_tests
Traceback (most recent call last):
  File "C:\Users\Celia\AppData\Local\Programs\Python\Python312\Lib\unittest\loader.py", line 129, in loadTestsFromName
    module = __import__(module_name)
             ^^^^^^^^^^^^^^^^^^^^^^^
  File "c:\users\celia\python_scripts\testingcenter\src\unittest\python\date_tests.py", line 3, in <module>
    from tester import Date
ModuleNotFoundError: No module named 'tester'

]]></error>
	</testcase>
	<testcase classname="unittest.loader._FailedTest" name="student_tests" time="0.002" timestamp="2024-06-29T20:47:34">
		<error type="ImportError" message="Failed to import test module: student_tests
Traceback (most recent call last):
  File &quot;C:\Users\Celia\AppData\Local\Programs\Python\Python312\Lib\unittest\loader.py&quot;, line 129, in loadTestsFromName
    module = __import__(module_name)
             ^^^^^^^^^^^^^^^^^^^^^^^
  File &quot;c:\users\celia\python_scripts\testingcenter\src\unittest\python\student_tests.py&quot;, line 3, in &lt;module&gt;
    from tester import Student
ModuleNotFoundError: No module named 'tester'
"><![CDATA[Traceback (most recent call last):
  File "C:\Users\Celia\AppData\Local\Programs\Python\Python312\Lib\unittest\case.py", line 58, in testPartExecutor
    yield
  File "C:\Users\Celia\AppData\Local\Programs\Python\Python312\Lib\unittest\case.py", line 634, in run
    self._callTestMethod(testMethod)
    ^^^^^^^^^^^^^^^^^
  File "C:\Users\Celia\AppData\Local\Programs\Python\Python312\Lib\unittest\case.py", line 589, in _callTestMethod
    if method() is not None:
    ^^^^^^^^^^^^^^^^^
  File "C:\Users\Celia\AppData\Local\Programs\Python\Python312\Lib\unittest\loader.py", line 33, in testFailure
    raise self._exception
    ^^^^^^^^^^^^^^^^^
ImportError: Failed to import test module: student_tests
Traceback (most recent call last):
  File "C:\Users\Celia\AppData\Local\Programs\Python\Python312\Lib\unittest\loader.py", line 129, in loadTestsFromName
    module = __import__(module_name)
             ^^^^^^^^^^^^^^^^^^^^^^^
  File "c:\users\celia\python_scripts\testingcenter\src\unittest\python\student_tests.py", line 3, in <module>
    from tester import Student
ModuleNotFoundError: No module named 'tester'

]]></error>
	</testcase>
</testsuite>
